<?xml version='1.0'?>

<robot name="my_robot" xmlns:xacro="http://www.ros.org/wiki/xacro">

  <xacro:include filename="$(find my_robot)/urdf/my_robot.gazebo" />

  <link name="robot_footprint"></link>

  <joint name="robot_footprint_joint" type="fixed">
    <origin xyz="0 0 0" rpy="0 0 0" />
    <parent link="robot_footprint"/>
    <child link="chassis" />
  </joint>



<!-- ##########################  CHASSIS LINK ############################-->

  <link name='chassis'>
    <pose>0 0 0.2 0 0 0</pose>

    <inertial>
      <mass value="15.0"/>
      <origin xyz="0.0 0 0" rpy=" 0 0 0"/>
      <inertia
          ixx="0.1" ixy="0" ixz="0"
          iyy="0.1" iyz="0"
          izz="0.1"
      />
    </inertial>

    <collision name='collision'>
      <origin xyz="0 0 0" rpy=" 0 0 0"/> 
      <geometry>
        <box size=".7 .3 .2"/>
      </geometry>
    </collision>

    <visual name='chassis_visual'>
      <origin xyz="0 0 0" rpy=" 0 0 0"/>
      <geometry>
        <box size=".7 .3 .2"/>
      </geometry>
    </visual>


    <collision name='back_caster_collision'>
      <origin xyz="-0.25 0 -0.1" rpy=" 0 0 0"/>
      <geometry>
        <sphere radius="0.0499"/>
      </geometry>
    </collision>

    <visual name='back_caster_visual'>
      <origin xyz="-0.25 0 -0.1" rpy=" 0 0 0"/>
      <geometry>
        <sphere radius="0.05"/>
      </geometry>
    </visual>

    <collision name='front_caster_collision'>
      <origin xyz="0.25 0 -0.1" rpy=" 0 0 0"/>
      <geometry>
        <sphere radius="0.0499"/>
      </geometry>
    </collision>

    <visual name='front_caster_visual'>
      <origin xyz="0.25 0 -0.1" rpy=" 0 0 0"/>
      <geometry>
        <sphere radius="0.05"/>
      </geometry>
    </visual>

  </link>


<!-- ##########################  LEFT WHEEL LINK ############################-->


  <link name='left_wheel'>

    <inertial>
      <mass value="5.0"/>
      <origin xyz="0.0 0 0" rpy=" 0 1.5707 1.5707"/>
      <inertia
          ixx="0.1" ixy="0" ixz="0"
          iyy="0.1" iyz="0"
          izz="0.1"
      />
    </inertial>

    <collision name='left_wheel_collision'>
      <origin xyz="0 0 0" rpy=" 0 1.5707 1.5707"/> 
      <geometry>
        <cylinder radius="0.15" length="0.05"/>
      </geometry>
    </collision>

    <visual name='left_wheel_visual'>
      <origin xyz="0 0 0" rpy=" 0 1.5707 1.5707"/> 
      <geometry>
        <cylinder radius="0.15" length="0.05"/>
      </geometry>
    </visual>

  </link>


<!-- ##########################  LEFT WHEEL JOINT ############################-->

  <joint type="continuous" name="left_wheel_hinge">
    <origin xyz="0 0.2 0" rpy="0 0 0"/>
    <child link="left_wheel"/>
    <parent link="chassis"/>
    <axis xyz="0 1 0" rpy="0 0 0"/>
    <limit effort="10000" velocity="1000"/>
    <dynamics damping="1.0" friction="1.0"/>
  </joint>


<!-- ##########################  RIGHT WHEEL LINK ############################-->

  <link name='right_wheel'>

    <inertial>
      <mass value="5.0"/>
      <origin xyz="0.0 0 0" rpy=" 0 1.5707 1.5707"/>
      <inertia
          ixx="0.1" ixy="0" ixz="0"
          iyy="0.1" iyz="0"
          izz="0.1"
      />
    </inertial>

    <collision name='right_wheel_collision'>
      <origin xyz="0 0 0" rpy=" 0 1.5707 1.5707"/> 
      <geometry>
        <cylinder radius="0.15" length="0.05"/>
      </geometry>
    </collision>

    <visual name='right_wheel_visual'>
      <origin xyz="0 0 0" rpy=" 0 1.5707 1.5707"/> 
      <geometry>
        <cylinder radius="0.15" length="0.05"/>
      </geometry>
    </visual>

  </link>

<!-- ##########################  RIGHT WHEEL JOINT ############################-->

  <joint type="continuous" name="right_wheel_hinge">
    <origin xyz="0 -0.2 0" rpy="0 0 0"/>
    <child link="right_wheel"/>
    <parent link="chassis"/>
    <axis xyz="0 1 0" rpy="0 0 0"/>
    <limit effort="10000" velocity="1000"/>
    <dynamics damping="1.0" friction="1.0"/>
  </joint>


<!-- ##########################  CAMERA LINK  ############################-->

  <link name='camera'>

    <inertial>
      <mass value="0.1"/>
      <origin xyz="0.05 0.05 0.05" rpy="0 0 0 "/>
      <inertia
          ixx="1e-6" ixy="0" ixz="0"
          iyy="1e-6" iyz="0"
          izz="1e-6"
      />
    </inertial>


    <visual name='camera_visual'>
      <origin xyz="0 0 0" rpy=" 0 0 0"/> 
      <geometry>
        <box size="0.05 0.075 0.075"/>
      </geometry>
    </visual>


    <collision name='camera_collision'>
      <origin xyz="0 0 0" rpy="0 0 0"/> 
      <geometry>
        <box size="0.05 0.075 0.075"/>
      </geometry>
    </collision>


  </link>

<!-- ##########################  CAMERA JOINT ############################-->

  <joint type="fixed" name="camera_joint">
    <origin xyz="0.375 0 0" rpy="0 0 0"/>
    <child link="camera"/>
    <parent link="chassis"/>
    <axis xyz="0 1 0" rpy="0 0 0"/>
    <!-- <limit effort="10000" velocity="1000"/> -->
    <!-- <dynamics damping="1.0" friction="1.0"/> -->
  </joint>



<!-- ##########################  CAMERA OPTICAL LINK ############################-->
  <link name="camera_link_optical">
  </link>


<!-- ##########################  CAMERA OPTICAL JOINT ############################-->
  <joint name="camera_optical_joint" type="fixed">
    <origin xyz="0 0 0" rpy="-1.5707 0 -1.5707"/>
    <parent link="camera"/>
    <child link="camera_link_optical"/>
  </joint>



<!-- ##########################  HOKUYO LIDAR LINK  ############################-->

  <link name='hokuyo'>

    <inertial>
      <mass value="1e-5"/>
      <origin xyz="0.0 0.0 0.0" rpy="0 0 0 "/>
      <inertia
          ixx="1e-6" ixy="0" ixz="0"
          iyy="1e-6" iyz="0"
          izz="1e-6"
      />
    </inertial>


    <visual name='hokuyo_visual'>
      <origin xyz="0 0 0" rpy=" 0 0 0"/> 
      <geometry>
        <mesh filename="package://my_robot/meshes/hokuyo.dae"/>
      </geometry>
    </visual>


    <collision name='hokuyo_collision'>
      <origin xyz="0 0 0" rpy="0 0 0"/> 
      <geometry>
        <box size="0.1 0.1 0.1"/>
      </geometry>
    </collision>


  </link>


 <!-- ##########################  HOKUYO LIDAR JOINT  ############################-->

  <joint type="fixed" name="hokuyo_joint">
    <origin xyz="0.3 0 0.165" rpy="0 0 0"/>
    <child link="hokuyo"/>
    <parent link="chassis"/>
    <axis xyz="0 1 0" rpy="0 0 0"/>
  </joint>


<!-- ##########################  COLOR  ############################-->

<gazebo reference="left_wheel">
    <material>Gazebo/Blue</material>
</gazebo>

<gazebo reference="right_wheel">
    <material>Gazebo/Blue</material>
</gazebo>

<gazebo reference="camera">
    <material>Gazebo/GreenGlow</material>
</gazebo>

<gazebo reference="chassis">
    <material>Gazebo/Orange</material>
</gazebo>


<!-- ##########################  COLOR  ############################-->

<!--   <material name="blue">
   <color rgba="0 0 0.8 1"/>
  </material>

  <material name="white">
   <color rgba="1 1 1 1"/>
  </material>
 -->


</robot>

